<mujoco model="onshape">
  <compiler angle="radian" meshdir="assets" autolimits="true"/>

  <!-- TODO: This line could be a source of error (idrk what it does) -->
  <option impratio="10"/>

  <default>
    <joint damping="0.5" frictionloss="0.01" armature="0.0002"/>

    <default class="servo">
      <position kp="3" ctrlrange="-0.0872665 0.0872665" forcerange="-5 5"/>
    </default>
    
    <default class="solenoid">
      <joint damping="0.1"/>
      <!-- <position kp="3" ctrlrange="-0.523599 0" forcerange="-5 5"/> -->
      <position kp="50" ctrlrange="0 0.523599" forcerange="-50 50"/>
      <!-- <position kp="5" ctrlrange="-0.4 0" forcerange="-5 5"/> -->
    </default>
    
    <default class="stepper">
      <joint damping="28" type="slide" axis="0 1 0"/>
      <position kp="50" ctrlrange="-2 2"/>
    </default>
  </default>

  <asset>
    <material name="dark_grey" specular="0.5" shininess="0.25" rgba="0.4 0.4 0.4 1"/>
    <material name="gray" specular="0.0" shininess="0.25" rgba="0.80848 0.80848 0.80848 1"/>
    <material name="metallic" specular="0" shininess="0.25" rgba="0.9 0.9 0.9 1"/>
    <material name="black" specular="0" shininess="0.25" rgba="0.3 0.3 0.3 1"/>

    <mesh name="servo" file="servo.stl"/>
    <mesh name="finger_mount_plate" file="finger_mount_plate.stl"/>
    <mesh name="servo_mechanism_top_mount" file="servo_mechanism_top_mount.stl"/>
    <mesh name="large_solenoid" file="large_solenoid.stl"/>
    <mesh name="large_finger_solenoid" file="large_finger_solenoid.stl"/>
    <mesh name="finger_arm_large" file="finger_arm_large.stl"/>
  </asset>

  <worldbody>
    <body name="finger_mount_plate" axisangle="0 0 1 3.1415926">
      <joint class="stepper" name="base_link_to_base" pos="0 0 0" axis="0 1 0" type="slide" range="-2 2" />
      <geom pos="0.0459382 -0.0438465 0.0782" quat="0 0 1 0" type="mesh" rgba="0.301961 0.313726 0.8 1" mesh="servo"/>
      <geom pos="0.0459382 -0.00634647 0.0782" quat="0 0 1 0" type="mesh" rgba="0.301961 0.313726 0.8 1" mesh="servo"/>
      <geom pos="0.00234993 0.0338035 -0.0218" quat="1 0 0 0" type="mesh" mesh="finger_mount_plate" material="dark_grey"/>
      <geom pos="0.0459382 0.0686535 0.0782" quat="0 0 1 0" type="mesh" rgba="0.301961 0.313726 0.8 1" mesh="servo"/>
      <geom pos="0.0459382 0.0311535 0.0782" quat="0 0 1 0" type="mesh" rgba="0.301961 0.313726 0.8 1" mesh="servo"/>
      <geom pos="0.00234327 3.51764e-06 0.06" quat="0 1 0 0" type="mesh" mesh="servo_mechanism_top_mount" material="dark_grey"/>
      <geom pos="0.0459382 -0.0813465 0.0782" quat="0 0 1 0" type="mesh" rgba="0.301961 0.313726 0.8 1" mesh="servo"/>
      <body name="large_finger_solenoid_1" pos="0.0353238 0.0750035 0.005" quat="0 0.707107 -0.707107 0">
        <inertial pos="1.7277e-08 0.0235491 -0.0213262" quat="0.706216 0.707996 4.01295e-06 -3.36093e-07" mass="0.553386" diaginertia="0.000162875 0.000146852 7.46131e-05"/>
        <joint name="Finger_Mount1" pos="0 0 0" axis="0 0 1" range="-0.0872665 0.0872665" actuatorfrcrange="-1 1"/>
        <geom pos="0 0.0273591 -0.036" quat="1 0 0 0" type="mesh" material="metallic" mesh="large_solenoid"/>
        <geom pos="0 0.007493 0" quat="0 1 0 0" type="mesh" material="black" mesh="large_finger_solenoid"/>
        <body name="finger_arm_large_1" pos="0.003 -0.029898 -0.046304" quat="0.5 -0.5 0.5 -0.5">
          <inertial pos="0.0513272 -0.00213016 -0.00250002" quat="0.0242961 0.706689 -0.0242961 0.706689" mass="0.00797272" diaginertia="1.16167e-05 1.11055e-05 5.43165e-07"/>
          <joint name="Finger_Arm1" pos="0 0 0" axis="0 0 -1" range="0 0.523599" actuatorfrcrange="-1 1"/>
          <geom pos="0.0633683 -5.47873e-05 -0.005" quat="1 0 0 0" type="mesh" rgba="0.972549 0.529412 0.00392157 1" mesh="finger_arm_large"/>
        </body>
      </body>
      <body name="large_finger_solenoid_2" pos="0.0353238 0.0375035 0.005" quat="0 0.707107 -0.707107 0">
        <inertial pos="1.7277e-08 0.0235491 -0.0213262" quat="0.706216 0.707996 4.01295e-06 -3.36093e-07" mass="0.553386" diaginertia="0.000162875 0.000146852 7.46131e-05"/>
        <joint name="Finger_Mount2" pos="0 0 0" axis="0 0 1" range="-0.0872665 0.0872665" actuatorfrcrange="-1 1"/>
        <geom pos="0 0.0273591 -0.036" quat="1 0 0 0" type="mesh" material="metallic" mesh="large_solenoid"/>
        <geom pos="0 0.007493 0" quat="0 1 0 0" type="mesh" material="black" mesh="large_finger_solenoid"/>
        <body name="finger_arm_large_2" pos="0.003 -0.029898 -0.046304" quat="0.5 -0.5 0.5 -0.5">
          <inertial pos="0.0513272 -0.00213016 -0.00250002" quat="0.0242961 0.706689 -0.0242961 0.706689" mass="0.00797272" diaginertia="1.16167e-05 1.11055e-05 5.43165e-07"/>
          <joint name="Finger_Arm2" pos="0 0 0" axis="0 0 -1" range="0 0.523599" actuatorfrcrange="-1 1"/>
          <geom pos="0.0633683 -5.47873e-05 -0.005" quat="1 0 0 0" type="mesh" rgba="0.972549 0.529412 0.00392157 1" mesh="finger_arm_large"/>
        </body>
      </body>
      <body name="large_finger_solenoid_3" pos="0.0353238 3.51764e-06 0.005" quat="0 0.707107 -0.707107 0">
        <inertial pos="1.7277e-08 0.0235491 -0.0213262" quat="0.706216 0.707996 4.01295e-06 -3.36093e-07" mass="0.553386" diaginertia="0.000162875 0.000146852 7.46131e-05"/>
        <joint name="Finger_Mount3" pos="0 0 0" axis="0 0 1" range="-0.0872665 0.0872665" actuatorfrcrange="-1 1"/>
        <geom pos="0 0.0273591 -0.036" quat="1 0 0 0" type="mesh" material="metallic" mesh="large_solenoid"/>
        <geom pos="0 0.007493 0" quat="0 1 0 0" type="mesh" material="black" mesh="large_finger_solenoid"/>
        <body name="finger_arm_large_3" pos="0.003 -0.029898 -0.046304" quat="0.5 -0.5 0.5 -0.5">
          <inertial pos="0.0513272 -0.00213016 -0.00250002" quat="0.0242961 0.706689 -0.0242961 0.706689" mass="0.00797272" diaginertia="1.16167e-05 1.11055e-05 5.43165e-07"/>
          <joint name="Finger_Arm3" pos="0 0 0" axis="0 0 -1" range="0 0.523599" actuatorfrcrange="-1 1"/>
          <geom pos="0.0633683 -5.47873e-05 -0.005" quat="1 0 0 0" type="mesh" rgba="0.972549 0.529412 0.00392157 1" mesh="finger_arm_large"/>
        </body>
      </body>
      <body name="large_finger_solenoid_4" pos="0.0353238 -0.0374965 0.005" quat="0 0.707107 -0.707107 0">
        <inertial pos="1.7277e-08 0.0235491 -0.0213262" quat="0.706216 0.707996 4.01295e-06 -3.36093e-07" mass="0.553386" diaginertia="0.000162875 0.000146852 7.46131e-05"/>
        <joint name="Finger_Mount4" pos="0 0 0" axis="0 0 1" range="-0.0872665 0.0872665" actuatorfrcrange="-1 1"/>
        <geom pos="0 0.0273591 -0.036" quat="1 0 0 0" type="mesh" material="metallic" mesh="large_solenoid"/>
        <geom pos="0 0.007493 0" quat="0 1 0 0" type="mesh" material="black" mesh="large_finger_solenoid"/>
        <body name="finger_arm_large_4" pos="0.003 -0.029898 -0.046304" quat="0.5 -0.5 0.5 -0.5">
          <inertial pos="0.0513272 -0.00213016 -0.00250002" quat="0.0242961 0.706689 -0.0242961 0.706689" mass="0.00797272" diaginertia="1.16167e-05 1.11055e-05 5.43165e-07"/>
          <joint name="Finger_Arm4" pos="0 0 0" axis="0 0 -1" range="0 0.523599" actuatorfrcrange="-1 1"/>
          <geom pos="0.0633683 -5.47873e-05 -0.005" quat="1 0 0 0" type="mesh" rgba="0.972549 0.529412 0.00392157 1" mesh="finger_arm_large"/>
        </body>
      </body>
      <body name="large_finger_solenoid_5" pos="0.0353238 -0.0749965 0.005" quat="0 0.707107 -0.707107 0">
        <inertial pos="1.7277e-08 0.0235491 -0.0213262" quat="0.706216 0.707996 4.01295e-06 -3.36093e-07" mass="0.553386" diaginertia="0.000162875 0.000146852 7.46131e-05"/>
        <joint name="Finger_Mount5" pos="0 0 0" axis="0 0 1" range="-0.0872665 0.0872665" actuatorfrcrange="-1 1"/>
        <geom pos="0 0.0273591 -0.036" quat="1 0 0 0" type="mesh" material="metallic" mesh="large_solenoid"/>
        <geom pos="0 0.007493 0" quat="0 1 0 0" type="mesh" material="black" mesh="large_finger_solenoid"/>
        <body name="finger_arm_large_5" pos="0.003 -0.029898 -0.046304" quat="0.5 -0.5 0.5 -0.5">
          <inertial pos="0.0513272 -0.00213016 -0.00250002" quat="0.0242961 0.706689 -0.0242961 0.706689" mass="0.00797272" diaginertia="1.16167e-05 1.11055e-05 5.43165e-07"/>
          <joint name="Finger_Arm5" pos="0 0 0" axis="0 0 -1" range="0 0.523599" actuatorfrcrange="-1 1"/>
          <geom pos="0.0633683 -5.47873e-05 -0.005" quat="1 0 0 0" type="mesh" rgba="0.972549 0.529412 0.00392157 1" mesh="finger_arm_large"/>
        </body>
      </body>
    </body>
  </worldbody>

  <contact>
    <exclude body1="finger_mount_plate" body2="large_finger_solenoid_1"/>
    <exclude body1="finger_mount_plate" body2="large_finger_solenoid_2"/>
    <exclude body1="finger_mount_plate" body2="large_finger_solenoid_3"/>
    <exclude body1="finger_mount_plate" body2="large_finger_solenoid_4"/>
    <exclude body1="finger_mount_plate" body2="large_finger_solenoid_5"/>

    <exclude body1="finger_mount_plate" body2="finger_arm_large_1"/>
    <exclude body1="finger_mount_plate" body2="finger_arm_large_2"/>
    <exclude body1="finger_mount_plate" body2="finger_arm_large_3"/>
    <exclude body1="finger_mount_plate" body2="finger_arm_large_4"/>
    <exclude body1="finger_mount_plate" body2="finger_arm_large_5"/>
  </contact>


  <actuator>
    <position name="stepper" joint="base_link_to_base" class="stepper"/>
    
    <position name="servo_1" joint="Finger_Mount1" class="servo"/>
    <position name="solenoid_1" joint="Finger_Arm1" class="solenoid"/>

    <position name="servo_2" joint="Finger_Mount2" class="servo"/>
    <position name="solenoid_2" joint="Finger_Arm2" class="solenoid"/>

    <position name="servo_3" joint="Finger_Mount3" class="servo"/>
    <position name="solenoid_3" joint="Finger_Arm3" class="solenoid"/>

    <position name="servo_4" joint="Finger_Mount4" class="servo"/>
    <position name="solenoid_4" joint="Finger_Arm4" class="solenoid"/>

    <position name="servo_5" joint="Finger_Mount5" class="servo"/>
    <position name="solenoid_5" joint="Finger_Arm5" class="solenoid"/>
  </actuator>
</mujoco>
